1..15
# Started on 02/27/17 18:21:41
# Starting class: TestTiti
not ok 1	TestTiti.test1_withFailure
#   example_with_luaunit.lua:104: expected: 2, actual: 1
#   stack traceback:
#   	example_with_luaunit.lua:104: in function 'TestTiti.test1_withFailure'
not ok 2	TestTiti.test2_withFailure
#   example_with_luaunit.lua:113: expected: "bof"
#   actual: "hop"
#   stack traceback:
#   	example_with_luaunit.lua:113: in function 'TestTiti.test2_withFailure'
ok     3	TestTiti.test3
# Starting class: TestToto
not ok 4	TestToto.test1_withFailure
#   example_with_luaunit.lua:21: expected: 2, actual: 1
#   stack traceback:
#   	example_with_luaunit.lua:21: in function 'TestToto.test1_withFailure'
not ok 5	TestToto.test2_withFailure
#   example_with_luaunit.lua:30: expected: "bof"
#   actual: "hop"
#   stack traceback:
#   	example_with_luaunit.lua:30: in function 'TestToto.test2_withFailure'
ok     6	TestToto.test3
not ok 7	TestToto.test4
#   example_with_luaunit.lua:43: Received the not expected value: 1
#   stack traceback:
#   	example_with_luaunit.lua:43: in function 'TestToto.test4'
not ok 8	TestToto.test5
#   example_with_luaunit.lua:49: expected: false or nil, actual: 1
#   stack traceback:
#   	example_with_luaunit.lua:49: in function 'TestToto.test5'
not ok 9	TestToto.test6
#   example_with_luaunit.lua:57: expected: false, actual: nil
#   stack traceback:
#   	example_with_luaunit.lua:57: in function 'TestToto.test6'
not ok 10	TestToto.test7
#   example_with_luaunit.lua:63: expected: {1, 2, three=3}
#   actual: {1, 2}
#   stack traceback:
#   	example_with_luaunit.lua:63: in function 'TestToto.test7'
not ok 11	TestToto.test8a
#   example_with_luaunit.lua:81: Bouhouhoum error!
#   stack traceback:
#   	example_with_luaunit.lua:81: in function 'funcWithError'
#   	example_with_luaunit.lua:68: in function 'TestToto.test8a'
not ok 12	TestToto.test8b
#   example_with_luaunit.lua:81: Bouhouhoum error!
#   stack traceback:
#   	example_with_luaunit.lua:81: in function 'funcWithError'
#   	example_with_luaunit.lua:77: in function 'funcWithFuncWithError'
#   	example_with_luaunit.lua:73: in function 'TestToto.test8b'
not ok 13	test1_withFailure
#   example_with_luaunit.lua:129: assertion failed!
#   stack traceback:
#   	example_with_luaunit.lua:129: in function 'test1_withFailure'
not ok 14	test2_withFailure
#   example_with_luaunit.lua:135: assertion failed!
#   stack traceback:
#   	example_with_luaunit.lua:135: in function 'test2_withFailure'
ok     15	test3
# Ran 15 tests in 0.002 seconds, 3 successes, 8 failures, 4 errors
