<?xml version="1.0" encoding="UTF-8" ?>
<testsuites>
    <testsuite name="LuaUnit" id="00001" package="" hostname="localhost" tests="15" timestamp="2016-01-30T22:33:12" time="0.000" errors="4" failures="8">
        <properties>
            <property name="Lua Version" value="Lua 5.2"/>
            <property name="LuaUnit Version" value="3.3"/>
        </properties>
        <testcase classname="TestTiti" name="TestTiti.test1_withFailure" time="0.000">
            <failure type="example_with_luaunit.lua:104: expected: 2, actual: 1">
                <![CDATA[stack traceback:
	example_with_luaunit.lua:104: in function 'TestTiti.test1_withFailure']]></failure>
        </testcase>
        <testcase classname="TestTiti" name="TestTiti.test2_withFailure" time="0.000">
            <failure type="example_with_luaunit.lua:113: expected: &quot;bof&quot;
actual: &quot;hop&quot;">
                <![CDATA[stack traceback:
	example_with_luaunit.lua:113: in function 'TestTiti.test2_withFailure']]></failure>
        </testcase>
        <testcase classname="TestTiti" name="TestTiti.test3" time="0.000">
        </testcase>
        <testcase classname="TestToto" name="TestToto.test1_withFailure" time="0.000">
            <failure type="example_with_luaunit.lua:21: expected: 2, actual: 1">
                <![CDATA[stack traceback:
	example_with_luaunit.lua:21: in function 'TestToto.test1_withFailure']]></failure>
        </testcase>
        <testcase classname="TestToto" name="TestToto.test2_withFailure" time="0.000">
            <failure type="example_with_luaunit.lua:30: expected: &quot;bof&quot;
actual: &quot;hop&quot;">
                <![CDATA[stack traceback:
	example_with_luaunit.lua:30: in function 'TestToto.test2_withFailure']]></failure>
        </testcase>
        <testcase classname="TestToto" name="TestToto.test3" time="0.000">
        </testcase>
        <testcase classname="TestToto" name="TestToto.test4" time="0.000">
            <failure type="example_with_luaunit.lua:43: Received the not expected value: 1">
                <![CDATA[stack traceback:
	example_with_luaunit.lua:43: in function 'TestToto.test4']]></failure>
        </testcase>
        <testcase classname="TestToto" name="TestToto.test5" time="0.000">
            <failure type="example_with_luaunit.lua:49: expected: false or nil, actual: 1">
                <![CDATA[stack traceback:
	example_with_luaunit.lua:49: in function 'TestToto.test5']]></failure>
        </testcase>
        <testcase classname="TestToto" name="TestToto.test6" time="0.000">
            <failure type="example_with_luaunit.lua:57: expected: false, actual: nil">
                <![CDATA[stack traceback:
	example_with_luaunit.lua:57: in function 'TestToto.test6']]></failure>
        </testcase>
        <testcase classname="TestToto" name="TestToto.test7" time="0.000">
            <failure type="example_with_luaunit.lua:63: expected: {1, 2, three=3}
actual: {1, 2}">
                <![CDATA[stack traceback:
	example_with_luaunit.lua:63: in function 'TestToto.test7']]></failure>
        </testcase>
        <testcase classname="TestToto" name="TestToto.test8a" time="0.000">
            <error type="example_with_luaunit.lua:81: Bouhouhoum error!">
                <![CDATA[stack traceback:
	example_with_luaunit.lua:81: in function 'funcWithError'
	example_with_luaunit.lua:68: in function 'TestToto.test8a']]></error>
        </testcase>
        <testcase classname="TestToto" name="TestToto.test8b" time="0.000">
            <error type="example_with_luaunit.lua:81: Bouhouhoum error!">
                <![CDATA[stack traceback:
	example_with_luaunit.lua:81: in function 'funcWithError'
	example_with_luaunit.lua:77: in function 'funcWithFuncWithError'
	example_with_luaunit.lua:73: in function 'TestToto.test8b']]></error>
        </testcase>
        <testcase classname="[TestFunctions]" name="test1_withFailure" time="0.000">
            <error type="example_with_luaunit.lua:129: assertion failed!">
                <![CDATA[stack traceback:
	example_with_luaunit.lua:129: in function 'test1_withFailure']]></error>
        </testcase>
        <testcase classname="[TestFunctions]" name="test2_withFailure" time="0.000">
            <error type="example_with_luaunit.lua:135: assertion failed!">
                <![CDATA[stack traceback:
	example_with_luaunit.lua:135: in function 'test2_withFailure']]></error>
        </testcase>
        <testcase classname="[TestFunctions]" name="test3" time="0.000">
        </testcase>
    <system-out/>
    <system-err/>
    </testsuite>
</testsuites>
